<?xml version="1.0" ?>
<robot name="(Unsaved)" xmlns:xacro="http://www.ros.org/wiki/xacro">

<xacro:include filename="$(find (Unsaved)_description)/urdf/materials.xacro" />
<xacro:include filename="$(find (Unsaved)_description)/urdf/(Unsaved).trans" />
<xacro:include filename="$(find (Unsaved)_description)/urdf/(Unsaved).gazebo" />
<link name="base_link">
  <inertial>
    <origin xyz="-2.5472957734337175e-13 0.019993521445171105 -0.0006133031904653681" rpy="0 0 0"/>
    <mass value="1.2850428455001575"/>
    <inertia ixx="0.004483" iyy="0.006696" izz="0.002568" ixy="-0.0" iyz="-1e-06" ixz="-0.0"/>
  </inertial>
  <visual>
    <origin xyz="0 0 0" rpy="0 0 0"/>
    <geometry>
      <mesh filename="package://(Unsaved)_description/meshes/base_link.stl" scale="0.001 0.001 0.001"/>
    </geometry>
    <material name="silver"/>
  </visual>
  <collision>
    <origin xyz="0 0 0" rpy="0 0 0"/>
    <geometry>
      <mesh filename="package://(Unsaved)_description/meshes/base_link.stl" scale="0.001 0.001 0.001"/>
    </geometry>
  </collision>
</link>

<link name="left_wheel_1">
  <inertial>
    <origin xyz="0.009999999999999995 0.0 1.3877787807814457e-17" rpy="0 0 0"/>
    <mass value="0.09349379737083224"/>
    <inertia ixx="7.5e-05" iyy="4.1e-05" izz="4.1e-05" ixy="0.0" iyz="0.0" ixz="0.0"/>
  </inertial>
  <visual>
    <origin xyz="-0.08 -0.02 -0.08" rpy="0 0 0"/>
    <geometry>
      <mesh filename="package://(Unsaved)_description/meshes/left_wheel_1.stl" scale="0.001 0.001 0.001"/>
    </geometry>
    <material name="silver"/>
  </visual>
  <collision>
    <origin xyz="-0.08 -0.02 -0.08" rpy="0 0 0"/>
    <geometry>
      <mesh filename="package://(Unsaved)_description/meshes/left_wheel_1.stl" scale="0.001 0.001 0.001"/>
    </geometry>
  </collision>
</link>

<link name="right_wheel_1">
  <inertial>
    <origin xyz="-0.009999999999999995 0.0 0.0" rpy="0 0 0"/>
    <mass value="0.09349379737083224"/>
    <inertia ixx="7.5e-05" iyy="4.1e-05" izz="4.1e-05" ixy="0.0" iyz="0.0" ixz="-0.0"/>
  </inertial>
  <visual>
    <origin xyz="0.08 -0.02 -0.08" rpy="0 0 0"/>
    <geometry>
      <mesh filename="package://(Unsaved)_description/meshes/right_wheel_1.stl" scale="0.001 0.001 0.001"/>
    </geometry>
    <material name="silver"/>
  </visual>
  <collision>
    <origin xyz="0.08 -0.02 -0.08" rpy="0 0 0"/>
    <geometry>
      <mesh filename="package://(Unsaved)_description/meshes/right_wheel_1.stl" scale="0.001 0.001 0.001"/>
    </geometry>
  </collision>
</link>

<link name="lidar_1">
  <inertial>
    <origin xyz="-4.523455546970335e-18 0.012500000000000004 0.0" rpy="0 0 0"/>
    <mass value="0.03330088212805181"/>
    <inertia ixx="5e-06" iyy="7e-06" izz="5e-06" ixy="-0.0" iyz="-0.0" ixz="0.0"/>
  </inertial>
  <visual>
    <origin xyz="-0.0 -0.045 0.07" rpy="0 0 0"/>
    <geometry>
      <mesh filename="package://(Unsaved)_description/meshes/lidar_1.stl" scale="0.001 0.001 0.001"/>
    </geometry>
    <material name="silver"/>
  </visual>
  <collision>
    <origin xyz="-0.0 -0.045 0.07" rpy="0 0 0"/>
    <geometry>
      <mesh filename="package://(Unsaved)_description/meshes/lidar_1.stl" scale="0.001 0.001 0.001"/>
    </geometry>
  </collision>
</link>

<joint name="Revolute 1" type="continuous">
  <origin xyz="0.08 0.02 0.08" rpy="0 0 0"/>
  <parent link="base_link"/>
  <child link="left_wheel_1"/>
  <axis xyz="1.0 0.0 0.0"/>
</joint>

<joint name="Revolute 2" type="continuous">
  <origin xyz="-0.08 0.02 0.08" rpy="0 0 0"/>
  <parent link="base_link"/>
  <child link="right_wheel_1"/>
  <axis xyz="-1.0 0.0 0.0"/>
</joint>

<joint name="Rigid 3" type="fixed">
  <origin xyz="0.0 0.045 -0.07" rpy="0 0 0"/>
  <parent link="base_link"/>
  <child link="lidar_1"/>
</joint>

</robot>
